Exception on / [GET]
Traceback (most recent call last):
  File "C:\Users\kth23\AppData\Local\Programs\Python\Python38\lib\site-packages\flask\app.py", line 2525, in wsgi_app
    response = self.full_dispatch_request()
  File "C:\Users\kth23\AppData\Local\Programs\Python\Python38\lib\site-packages\flask\app.py", line 1822, in full_dispatch_request
    rv = self.handle_user_exception(e)
  File "C:\Users\kth23\AppData\Local\Programs\Python\Python38\lib\site-packages\flask\app.py", line 1820, in full_dispatch_request
    rv = self.dispatch_request()
  File "C:\Users\kth23\AppData\Local\Programs\Python\Python38\lib\site-packages\flask\app.py", line 1796, in dispatch_request
    return self.ensure_sync(self.view_functions[rule.endpoint])(**view_args)
  File "C:\Users\kth23\OneDrive\¹®¼­\nodesoeasytest\app.py", line 40, in home
    conn = pymysql.connect(host='localhost',
  File "C:\Users\kth23\AppData\Local\Programs\Python\Python38\lib\site-packages\pymysql\connections.py", line 353, in __init__
    self.connect()
  File "C:\Users\kth23\AppData\Local\Programs\Python\Python38\lib\site-packages\pymysql\connections.py", line 633, in connect
    self._request_authentication()
  File "C:\Users\kth23\AppData\Local\Programs\Python\Python38\lib\site-packages\pymysql\connections.py", line 932, in _request_authentication
    auth_packet = _auth.caching_sha2_password_auth(self, auth_packet)
  File "C:\Users\kth23\AppData\Local\Programs\Python\Python38\lib\site-packages\pymysql\_auth.py", line 265, in caching_sha2_password_auth
    data = sha2_rsa_encrypt(conn.password, conn.salt, conn.server_public_key)
  File "C:\Users\kth23\AppData\Local\Programs\Python\Python38\lib\site-packages\pymysql\_auth.py", line 143, in sha2_rsa_encrypt
    raise RuntimeError(
RuntimeError: 'cryptography' package is required for sha256_password or caching_sha2_password auth methods
